2018-07-10 17:29:47,375 ERROR: Exception on / [GET] [in /home/kodi/anaconda3/lib/python3.6/site-packages/flask/app.py:1560]
Traceback (most recent call last):
  File "/home/kodi/anaconda3/lib/python3.6/site-packages/flask/app.py", line 1982, in wsgi_app
    response = self.full_dispatch_request()
  File "/home/kodi/anaconda3/lib/python3.6/site-packages/flask/app.py", line 1614, in full_dispatch_request
    rv = self.handle_user_exception(e)
  File "/home/kodi/anaconda3/lib/python3.6/site-packages/flask/app.py", line 1517, in handle_user_exception
    reraise(exc_type, exc_value, tb)
  File "/home/kodi/anaconda3/lib/python3.6/site-packages/flask/_compat.py", line 33, in reraise
    raise value
  File "/home/kodi/anaconda3/lib/python3.6/site-packages/flask/app.py", line 1612, in full_dispatch_request
    rv = self.dispatch_request()
  File "/home/kodi/anaconda3/lib/python3.6/site-packages/flask/app.py", line 1598, in dispatch_request
    return self.view_functions[rule.endpoint](**req.view_args)
  File "/home/kodi/anaconda3/lib/python3.6/site-packages/flask_login/utils.py", line 227, in decorated_view
    return current_app.login_manager.unauthorized()
  File "/home/kodi/anaconda3/lib/python3.6/site-packages/flask_login/login_manager.py", line 165, in unauthorized
    return redirect(login_url(login_view, request.url))
  File "/home/kodi/anaconda3/lib/python3.6/site-packages/flask_login/utils.py", line 97, in login_url
    base = url_for(login_view)
  File "/home/kodi/anaconda3/lib/python3.6/site-packages/flask/helpers.py", line 333, in url_for
    return appctx.app.handle_url_build_error(error, endpoint, values)
  File "/home/kodi/anaconda3/lib/python3.6/site-packages/flask/app.py", line 1805, in handle_url_build_error
    reraise(exc_type, exc_value, tb)
  File "/home/kodi/anaconda3/lib/python3.6/site-packages/flask/_compat.py", line 33, in reraise
    raise value
  File "/home/kodi/anaconda3/lib/python3.6/site-packages/flask/helpers.py", line 323, in url_for
    force_external=external)
  File "/home/kodi/anaconda3/lib/python3.6/site-packages/werkzeug/routing.py", line 1768, in build
    raise BuildError(endpoint, values, method, self)
werkzeug.routing.BuildError: Could not build url for endpoint 'login'. Did you mean 'auth.login' instead?
2018-07-10 17:30:39,354 INFO: Microblog startup [in /home/kodi/Workspace/parky/app/__init__.py:65]
2018-07-10 17:30:43,080 ERROR: Exception on / [GET] [in /home/kodi/anaconda3/lib/python3.6/site-packages/flask/app.py:1560]
Traceback (most recent call last):
  File "/home/kodi/anaconda3/lib/python3.6/site-packages/flask/app.py", line 1982, in wsgi_app
    response = self.full_dispatch_request()
  File "/home/kodi/anaconda3/lib/python3.6/site-packages/flask/app.py", line 1614, in full_dispatch_request
    rv = self.handle_user_exception(e)
  File "/home/kodi/anaconda3/lib/python3.6/site-packages/flask/app.py", line 1517, in handle_user_exception
    reraise(exc_type, exc_value, tb)
  File "/home/kodi/anaconda3/lib/python3.6/site-packages/flask/_compat.py", line 33, in reraise
    raise value
  File "/home/kodi/anaconda3/lib/python3.6/site-packages/flask/app.py", line 1612, in full_dispatch_request
    rv = self.dispatch_request()
  File "/home/kodi/anaconda3/lib/python3.6/site-packages/flask/app.py", line 1598, in dispatch_request
    return self.view_functions[rule.endpoint](**req.view_args)
  File "/home/kodi/anaconda3/lib/python3.6/site-packages/flask_login/utils.py", line 227, in decorated_view
    return current_app.login_manager.unauthorized()
  File "/home/kodi/anaconda3/lib/python3.6/site-packages/flask_login/login_manager.py", line 165, in unauthorized
    return redirect(login_url(login_view, request.url))
  File "/home/kodi/anaconda3/lib/python3.6/site-packages/flask_login/utils.py", line 97, in login_url
    base = url_for(login_view)
  File "/home/kodi/anaconda3/lib/python3.6/site-packages/flask/helpers.py", line 333, in url_for
    return appctx.app.handle_url_build_error(error, endpoint, values)
  File "/home/kodi/anaconda3/lib/python3.6/site-packages/flask/app.py", line 1805, in handle_url_build_error
    reraise(exc_type, exc_value, tb)
  File "/home/kodi/anaconda3/lib/python3.6/site-packages/flask/_compat.py", line 33, in reraise
    raise value
  File "/home/kodi/anaconda3/lib/python3.6/site-packages/flask/helpers.py", line 323, in url_for
    force_external=external)
  File "/home/kodi/anaconda3/lib/python3.6/site-packages/werkzeug/routing.py", line 1768, in build
    raise BuildError(endpoint, values, method, self)
werkzeug.routing.BuildError: Could not build url for endpoint 'login'. Did you mean 'auth.login' instead?
2018-07-10 17:32:08,514 INFO: Microblog startup [in /home/kodi/Workspace/parky/app/__init__.py:65]
2018-07-10 17:32:11,453 ERROR: Exception on / [GET] [in /home/kodi/anaconda3/lib/python3.6/site-packages/flask/app.py:1560]
Traceback (most recent call last):
  File "/home/kodi/anaconda3/lib/python3.6/site-packages/flask/app.py", line 1982, in wsgi_app
    response = self.full_dispatch_request()
  File "/home/kodi/anaconda3/lib/python3.6/site-packages/flask/app.py", line 1614, in full_dispatch_request
    rv = self.handle_user_exception(e)
  File "/home/kodi/anaconda3/lib/python3.6/site-packages/flask/app.py", line 1517, in handle_user_exception
    reraise(exc_type, exc_value, tb)
  File "/home/kodi/anaconda3/lib/python3.6/site-packages/flask/_compat.py", line 33, in reraise
    raise value
  File "/home/kodi/anaconda3/lib/python3.6/site-packages/flask/app.py", line 1612, in full_dispatch_request
    rv = self.dispatch_request()
  File "/home/kodi/anaconda3/lib/python3.6/site-packages/flask/app.py", line 1598, in dispatch_request
    return self.view_functions[rule.endpoint](**req.view_args)
  File "/home/kodi/anaconda3/lib/python3.6/site-packages/flask_login/utils.py", line 227, in decorated_view
    return current_app.login_manager.unauthorized()
  File "/home/kodi/anaconda3/lib/python3.6/site-packages/flask_login/login_manager.py", line 165, in unauthorized
    return redirect(login_url(login_view, request.url))
  File "/home/kodi/anaconda3/lib/python3.6/site-packages/flask_login/utils.py", line 97, in login_url
    base = url_for(login_view)
  File "/home/kodi/anaconda3/lib/python3.6/site-packages/flask/helpers.py", line 333, in url_for
    return appctx.app.handle_url_build_error(error, endpoint, values)
  File "/home/kodi/anaconda3/lib/python3.6/site-packages/flask/app.py", line 1805, in handle_url_build_error
    reraise(exc_type, exc_value, tb)
  File "/home/kodi/anaconda3/lib/python3.6/site-packages/flask/_compat.py", line 33, in reraise
    raise value
  File "/home/kodi/anaconda3/lib/python3.6/site-packages/flask/helpers.py", line 323, in url_for
    force_external=external)
  File "/home/kodi/anaconda3/lib/python3.6/site-packages/werkzeug/routing.py", line 1768, in build
    raise BuildError(endpoint, values, method, self)
werkzeug.routing.BuildError: Could not build url for endpoint 'login'. Did you mean 'auth.login' instead?
2018-07-10 17:34:31,748 INFO: Microblog startup [in /home/kodi/Workspace/parky/app/__init__.py:65]
2018-07-10 17:35:30,104 ERROR: Exception on / [GET] [in /home/kodi/anaconda3/lib/python3.6/site-packages/flask/app.py:1560]
Traceback (most recent call last):
  File "/home/kodi/anaconda3/lib/python3.6/site-packages/flask/app.py", line 1982, in wsgi_app
    response = self.full_dispatch_request()
  File "/home/kodi/anaconda3/lib/python3.6/site-packages/flask/app.py", line 1614, in full_dispatch_request
    rv = self.handle_user_exception(e)
  File "/home/kodi/anaconda3/lib/python3.6/site-packages/flask/app.py", line 1517, in handle_user_exception
    reraise(exc_type, exc_value, tb)
  File "/home/kodi/anaconda3/lib/python3.6/site-packages/flask/_compat.py", line 33, in reraise
    raise value
  File "/home/kodi/anaconda3/lib/python3.6/site-packages/flask/app.py", line 1612, in full_dispatch_request
    rv = self.dispatch_request()
  File "/home/kodi/anaconda3/lib/python3.6/site-packages/flask/app.py", line 1598, in dispatch_request
    return self.view_functions[rule.endpoint](**req.view_args)
  File "/home/kodi/anaconda3/lib/python3.6/site-packages/flask_login/utils.py", line 227, in decorated_view
    return current_app.login_manager.unauthorized()
  File "/home/kodi/anaconda3/lib/python3.6/site-packages/flask_login/login_manager.py", line 165, in unauthorized
    return redirect(login_url(login_view, request.url))
  File "/home/kodi/anaconda3/lib/python3.6/site-packages/flask_login/utils.py", line 97, in login_url
    base = url_for(login_view)
  File "/home/kodi/anaconda3/lib/python3.6/site-packages/flask/helpers.py", line 333, in url_for
    return appctx.app.handle_url_build_error(error, endpoint, values)
  File "/home/kodi/anaconda3/lib/python3.6/site-packages/flask/app.py", line 1805, in handle_url_build_error
    reraise(exc_type, exc_value, tb)
  File "/home/kodi/anaconda3/lib/python3.6/site-packages/flask/_compat.py", line 33, in reraise
    raise value
  File "/home/kodi/anaconda3/lib/python3.6/site-packages/flask/helpers.py", line 323, in url_for
    force_external=external)
  File "/home/kodi/anaconda3/lib/python3.6/site-packages/werkzeug/routing.py", line 1768, in build
    raise BuildError(endpoint, values, method, self)
werkzeug.routing.BuildError: Could not build url for endpoint 'login'. Did you mean 'auth.login' instead?
2018-07-10 17:35:35,371 INFO: Microblog startup [in /home/kodi/Workspace/parky/app/__init__.py:65]
