2018-07-10 17:28:33,156 ERROR: Exception on /admin/service [GET] [in /home/kodi/anaconda3/lib/python3.6/site-packages/flask/app.py:1560]
Traceback (most recent call last):
  File "/home/kodi/anaconda3/lib/python3.6/site-packages/sqlalchemy/engine/base.py", line 1182, in _execute_context
    context)
  File "/home/kodi/anaconda3/lib/python3.6/site-packages/sqlalchemy/engine/default.py", line 470, in do_execute
    cursor.execute(statement, parameters)
sqlite3.OperationalError: no such table: user

The above exception was the direct cause of the following exception:

Traceback (most recent call last):
  File "/home/kodi/anaconda3/lib/python3.6/site-packages/flask/app.py", line 1982, in wsgi_app
    response = self.full_dispatch_request()
  File "/home/kodi/anaconda3/lib/python3.6/site-packages/flask/app.py", line 1614, in full_dispatch_request
    rv = self.handle_user_exception(e)
  File "/home/kodi/anaconda3/lib/python3.6/site-packages/flask/app.py", line 1517, in handle_user_exception
    reraise(exc_type, exc_value, tb)
  File "/home/kodi/anaconda3/lib/python3.6/site-packages/flask/_compat.py", line 33, in reraise
    raise value
  File "/home/kodi/anaconda3/lib/python3.6/site-packages/flask/app.py", line 1612, in full_dispatch_request
    rv = self.dispatch_request()
  File "/home/kodi/anaconda3/lib/python3.6/site-packages/flask/app.py", line 1598, in dispatch_request
    return self.view_functions[rule.endpoint](**req.view_args)
  File "/home/kodi/anaconda3/lib/python3.6/site-packages/flask_login/utils.py", line 226, in decorated_view
    elif not current_user.is_authenticated:
  File "/home/kodi/anaconda3/lib/python3.6/site-packages/werkzeug/local.py", line 347, in __getattr__
    return getattr(self._get_current_object(), name)
  File "/home/kodi/anaconda3/lib/python3.6/site-packages/werkzeug/local.py", line 306, in _get_current_object
    return self.__local()
  File "/home/kodi/anaconda3/lib/python3.6/site-packages/flask_login/utils.py", line 26, in <lambda>
    current_user = LocalProxy(lambda: _get_user())
  File "/home/kodi/anaconda3/lib/python3.6/site-packages/flask_login/utils.py", line 302, in _get_user
    current_app.login_manager._load_user()
  File "/home/kodi/anaconda3/lib/python3.6/site-packages/flask_login/login_manager.py", line 317, in _load_user
    return self.reload_user()
  File "/home/kodi/anaconda3/lib/python3.6/site-packages/flask_login/login_manager.py", line 279, in reload_user
    user = self.user_callback(user_id)
  File "/home/kodi/Workspace/parky/app/models.py", line 120, in load_user
    return User.query.get(int(id))
  File "/home/kodi/anaconda3/lib/python3.6/site-packages/sqlalchemy/orm/query.py", line 864, in get
    return self._get_impl(ident, loading.load_on_ident)
  File "/home/kodi/anaconda3/lib/python3.6/site-packages/sqlalchemy/orm/query.py", line 897, in _get_impl
    return fallback_fn(self, key)
  File "/home/kodi/anaconda3/lib/python3.6/site-packages/sqlalchemy/orm/loading.py", line 223, in load_on_ident
    return q.one()
  File "/home/kodi/anaconda3/lib/python3.6/site-packages/sqlalchemy/orm/query.py", line 2814, in one
    ret = self.one_or_none()
  File "/home/kodi/anaconda3/lib/python3.6/site-packages/sqlalchemy/orm/query.py", line 2784, in one_or_none
    ret = list(self)
  File "/home/kodi/anaconda3/lib/python3.6/site-packages/sqlalchemy/orm/query.py", line 2855, in __iter__
    return self._execute_and_instances(context)
  File "/home/kodi/anaconda3/lib/python3.6/site-packages/sqlalchemy/orm/query.py", line 2878, in _execute_and_instances
    result = conn.execute(querycontext.statement, self._params)
  File "/home/kodi/anaconda3/lib/python3.6/site-packages/sqlalchemy/engine/base.py", line 945, in execute
    return meth(self, multiparams, params)
  File "/home/kodi/anaconda3/lib/python3.6/site-packages/sqlalchemy/sql/elements.py", line 263, in _execute_on_connection
    return connection._execute_clauseelement(self, multiparams, params)
  File "/home/kodi/anaconda3/lib/python3.6/site-packages/sqlalchemy/engine/base.py", line 1053, in _execute_clauseelement
    compiled_sql, distilled_params
  File "/home/kodi/anaconda3/lib/python3.6/site-packages/sqlalchemy/engine/base.py", line 1189, in _execute_context
    context)
  File "/home/kodi/anaconda3/lib/python3.6/site-packages/sqlalchemy/engine/base.py", line 1402, in _handle_dbapi_exception
    exc_info
  File "/home/kodi/anaconda3/lib/python3.6/site-packages/sqlalchemy/util/compat.py", line 203, in raise_from_cause
    reraise(type(exception), exception, tb=exc_tb, cause=cause)
  File "/home/kodi/anaconda3/lib/python3.6/site-packages/sqlalchemy/util/compat.py", line 186, in reraise
    raise value.with_traceback(tb)
  File "/home/kodi/anaconda3/lib/python3.6/site-packages/sqlalchemy/engine/base.py", line 1182, in _execute_context
    context)
  File "/home/kodi/anaconda3/lib/python3.6/site-packages/sqlalchemy/engine/default.py", line 470, in do_execute
    cursor.execute(statement, parameters)
sqlalchemy.exc.OperationalError: (sqlite3.OperationalError) no such table: user [SQL: 'SELECT user.id AS user_id, user.username AS user_username, user.email AS user_email, user.password_hash AS user_password_hash, user.about_me AS user_about_me, user.last_seen AS user_last_seen \nFROM user \nWHERE user.id = ?'] [parameters: (1,)]
2018-07-10 17:29:02,203 INFO: Microblog startup [in /home/kodi/Workspace/parky/app/__init__.py:65]
2018-07-10 17:29:11,703 INFO: Microblog startup [in /home/kodi/Workspace/parky/app/__init__.py:65]
2018-07-10 17:29:19,837 INFO: Microblog startup [in /home/kodi/Workspace/parky/app/__init__.py:65]
2018-07-10 17:29:29,043 INFO: Microblog startup [in /home/kodi/Workspace/parky/app/__init__.py:65]
2018-07-10 17:29:42,585 ERROR: Exception on /admin/service [GET] [in /home/kodi/anaconda3/lib/python3.6/site-packages/flask/app.py:1560]
Traceback (most recent call last):
  File "/home/kodi/anaconda3/lib/python3.6/site-packages/flask/app.py", line 1982, in wsgi_app
    response = self.full_dispatch_request()
  File "/home/kodi/anaconda3/lib/python3.6/site-packages/flask/app.py", line 1614, in full_dispatch_request
    rv = self.handle_user_exception(e)
  File "/home/kodi/anaconda3/lib/python3.6/site-packages/flask/app.py", line 1517, in handle_user_exception
    reraise(exc_type, exc_value, tb)
  File "/home/kodi/anaconda3/lib/python3.6/site-packages/flask/_compat.py", line 33, in reraise
    raise value
  File "/home/kodi/anaconda3/lib/python3.6/site-packages/flask/app.py", line 1612, in full_dispatch_request
    rv = self.dispatch_request()
  File "/home/kodi/anaconda3/lib/python3.6/site-packages/flask/app.py", line 1598, in dispatch_request
    return self.view_functions[rule.endpoint](**req.view_args)
  File "/home/kodi/anaconda3/lib/python3.6/site-packages/flask_login/utils.py", line 227, in decorated_view
    return current_app.login_manager.unauthorized()
  File "/home/kodi/anaconda3/lib/python3.6/site-packages/flask_login/login_manager.py", line 165, in unauthorized
    return redirect(login_url(login_view, request.url))
  File "/home/kodi/anaconda3/lib/python3.6/site-packages/flask_login/utils.py", line 97, in login_url
    base = url_for(login_view)
  File "/home/kodi/anaconda3/lib/python3.6/site-packages/flask/helpers.py", line 333, in url_for
    return appctx.app.handle_url_build_error(error, endpoint, values)
  File "/home/kodi/anaconda3/lib/python3.6/site-packages/flask/app.py", line 1805, in handle_url_build_error
    reraise(exc_type, exc_value, tb)
  File "/home/kodi/anaconda3/lib/python3.6/site-packages/flask/_compat.py", line 33, in reraise
    raise value
  File "/home/kodi/anaconda3/lib/python3.6/site-packages/flask/helpers.py", line 323, in url_for
    force_external=external)
  File "/home/kodi/anaconda3/lib/python3.6/site-packages/werkzeug/routing.py", line 1768, in build
    raise BuildError(endpoint, values, method, self)
werkzeug.routing.BuildError: Could not build url for endpoint 'login'. Did you mean 'auth.login' instead?
