2018-07-07 13:15:24,174 ERROR: Exception on /user/kodi [GET] [in /home/kodi/Workspace/parky/venv/lib/python3.6/site-packages/flask/app.py:1761]
Traceback (most recent call last):
  File "/home/kodi/Workspace/parky/venv/lib/python3.6/site-packages/flask/app.py", line 2292, in wsgi_app
    response = self.full_dispatch_request()
  File "/home/kodi/Workspace/parky/venv/lib/python3.6/site-packages/flask/app.py", line 1815, in full_dispatch_request
    rv = self.handle_user_exception(e)
  File "/home/kodi/Workspace/parky/venv/lib/python3.6/site-packages/flask/app.py", line 1718, in handle_user_exception
    reraise(exc_type, exc_value, tb)
  File "/home/kodi/Workspace/parky/venv/lib/python3.6/site-packages/flask/_compat.py", line 35, in reraise
    raise value
  File "/home/kodi/Workspace/parky/venv/lib/python3.6/site-packages/flask/app.py", line 1813, in full_dispatch_request
    rv = self.dispatch_request()
  File "/home/kodi/Workspace/parky/venv/lib/python3.6/site-packages/flask/app.py", line 1799, in dispatch_request
    return self.view_functions[rule.endpoint](**req.view_args)
  File "/home/kodi/Workspace/parky/venv/lib/python3.6/site-packages/flask_login/utils.py", line 261, in decorated_view
    return func(*args, **kwargs)
  File "/home/kodi/Workspace/parky/app/auth/routes.py", line 59, in user
    return render_template('auth/user.html', user=user, posts=posts)
  File "/home/kodi/Workspace/parky/venv/lib/python3.6/site-packages/flask/templating.py", line 135, in render_template
    context, ctx.app)
  File "/home/kodi/Workspace/parky/venv/lib/python3.6/site-packages/flask/templating.py", line 117, in _render
    rv = template.render(context)
  File "/home/kodi/Workspace/parky/venv/lib/python3.6/site-packages/jinja2/asyncsupport.py", line 76, in render
    return original_render(self, *args, **kwargs)
  File "/home/kodi/Workspace/parky/venv/lib/python3.6/site-packages/jinja2/environment.py", line 1008, in render
    return self.environment.handle_exception(exc_info, True)
  File "/home/kodi/Workspace/parky/venv/lib/python3.6/site-packages/jinja2/environment.py", line 780, in handle_exception
    reraise(exc_type, exc_value, tb)
  File "/home/kodi/Workspace/parky/venv/lib/python3.6/site-packages/jinja2/_compat.py", line 37, in reraise
    raise value.with_traceback(tb)
  File "/home/kodi/Workspace/parky/app/templates/auth/user.html", line 1, in top-level template code
    {% extends "base.html" %}
  File "/home/kodi/Workspace/parky/app/templates/base.html", line 34, in top-level template code
    {% block content %}{% endblock %}
  File "/home/kodi/Workspace/parky/app/templates/auth/user.html", line 19, in block "content"
    {% include '_post.html' %}
  File "/home/kodi/Workspace/parky/venv/lib/python3.6/site-packages/flask/templating.py", line 58, in get_source
    return self._get_source_fast(environment, template)
  File "/home/kodi/Workspace/parky/venv/lib/python3.6/site-packages/flask/templating.py", line 86, in _get_source_fast
    raise TemplateNotFound(template)
jinja2.exceptions.TemplateNotFound: _post.html
2018-07-07 13:16:42,297 ERROR: Exception on /user/kodi [GET] [in /home/kodi/Workspace/parky/venv/lib/python3.6/site-packages/flask/app.py:1761]
Traceback (most recent call last):
  File "/home/kodi/Workspace/parky/venv/lib/python3.6/site-packages/flask/app.py", line 2292, in wsgi_app
    response = self.full_dispatch_request()
  File "/home/kodi/Workspace/parky/venv/lib/python3.6/site-packages/flask/app.py", line 1815, in full_dispatch_request
    rv = self.handle_user_exception(e)
  File "/home/kodi/Workspace/parky/venv/lib/python3.6/site-packages/flask/app.py", line 1718, in handle_user_exception
    reraise(exc_type, exc_value, tb)
  File "/home/kodi/Workspace/parky/venv/lib/python3.6/site-packages/flask/_compat.py", line 35, in reraise
    raise value
  File "/home/kodi/Workspace/parky/venv/lib/python3.6/site-packages/flask/app.py", line 1813, in full_dispatch_request
    rv = self.dispatch_request()
  File "/home/kodi/Workspace/parky/venv/lib/python3.6/site-packages/flask/app.py", line 1799, in dispatch_request
    return self.view_functions[rule.endpoint](**req.view_args)
  File "/home/kodi/Workspace/parky/venv/lib/python3.6/site-packages/flask_login/utils.py", line 261, in decorated_view
    return func(*args, **kwargs)
  File "/home/kodi/Workspace/parky/app/auth/routes.py", line 59, in user
    return render_template('auth/user.html', user=user, posts=posts)
  File "/home/kodi/Workspace/parky/venv/lib/python3.6/site-packages/flask/templating.py", line 135, in render_template
    context, ctx.app)
  File "/home/kodi/Workspace/parky/venv/lib/python3.6/site-packages/flask/templating.py", line 117, in _render
    rv = template.render(context)
  File "/home/kodi/Workspace/parky/venv/lib/python3.6/site-packages/jinja2/asyncsupport.py", line 76, in render
    return original_render(self, *args, **kwargs)
  File "/home/kodi/Workspace/parky/venv/lib/python3.6/site-packages/jinja2/environment.py", line 1008, in render
    return self.environment.handle_exception(exc_info, True)
  File "/home/kodi/Workspace/parky/venv/lib/python3.6/site-packages/jinja2/environment.py", line 780, in handle_exception
    reraise(exc_type, exc_value, tb)
  File "/home/kodi/Workspace/parky/venv/lib/python3.6/site-packages/jinja2/_compat.py", line 37, in reraise
    raise value.with_traceback(tb)
  File "/home/kodi/Workspace/parky/app/templates/auth/user.html", line 1, in top-level template code
    {% extends "base.html" %}
  File "/home/kodi/Workspace/parky/app/templates/base.html", line 34, in top-level template code
    {% block content %}{% endblock %}
  File "/home/kodi/Workspace/parky/app/templates/auth/user.html", line 19, in block "content"
    {% include '_post.html' %}
  File "/home/kodi/Workspace/parky/venv/lib/python3.6/site-packages/flask/templating.py", line 58, in get_source
    return self._get_source_fast(environment, template)
  File "/home/kodi/Workspace/parky/venv/lib/python3.6/site-packages/flask/templating.py", line 86, in _get_source_fast
    raise TemplateNotFound(template)
jinja2.exceptions.TemplateNotFound: _post.html
2018-07-07 13:17:42,338 INFO: Microblog startup [in /home/kodi/Workspace/parky/app/__init__.py:65]
2018-07-07 13:18:20,549 INFO: Microblog startup [in /home/kodi/Workspace/parky/app/__init__.py:65]
2018-07-07 13:18:30,937 ERROR: Exception on /edit_profile [POST] [in /home/kodi/Workspace/parky/venv/lib/python3.6/site-packages/flask/app.py:1761]
Traceback (most recent call last):
  File "/home/kodi/Workspace/parky/venv/lib/python3.6/site-packages/flask/app.py", line 2292, in wsgi_app
    response = self.full_dispatch_request()
  File "/home/kodi/Workspace/parky/venv/lib/python3.6/site-packages/flask/app.py", line 1815, in full_dispatch_request
    rv = self.handle_user_exception(e)
  File "/home/kodi/Workspace/parky/venv/lib/python3.6/site-packages/flask/app.py", line 1718, in handle_user_exception
    reraise(exc_type, exc_value, tb)
  File "/home/kodi/Workspace/parky/venv/lib/python3.6/site-packages/flask/_compat.py", line 35, in reraise
    raise value
  File "/home/kodi/Workspace/parky/venv/lib/python3.6/site-packages/flask/app.py", line 1813, in full_dispatch_request
    rv = self.dispatch_request()
  File "/home/kodi/Workspace/parky/venv/lib/python3.6/site-packages/flask/app.py", line 1799, in dispatch_request
    return self.view_functions[rule.endpoint](**req.view_args)
  File "/home/kodi/Workspace/parky/venv/lib/python3.6/site-packages/flask_login/utils.py", line 261, in decorated_view
    return func(*args, **kwargs)
  File "/home/kodi/Workspace/parky/app/auth/routes.py", line 71, in edit_profile
    return redirect(url_for('edit_profile'))
  File "/home/kodi/Workspace/parky/venv/lib/python3.6/site-packages/flask/helpers.py", line 356, in url_for
    return appctx.app.handle_url_build_error(error, endpoint, values)
  File "/home/kodi/Workspace/parky/venv/lib/python3.6/site-packages/flask/app.py", line 2061, in handle_url_build_error
    reraise(exc_type, exc_value, tb)
  File "/home/kodi/Workspace/parky/venv/lib/python3.6/site-packages/flask/_compat.py", line 35, in reraise
    raise value
  File "/home/kodi/Workspace/parky/venv/lib/python3.6/site-packages/flask/helpers.py", line 345, in url_for
    force_external=external)
  File "/home/kodi/Workspace/parky/venv/lib/python3.6/site-packages/werkzeug/routing.py", line 1776, in build
    raise BuildError(endpoint, values, method, self)
werkzeug.routing.BuildError: Could not build url for endpoint 'edit_profile'. Did you mean 'auth.edit_profile' instead?
2018-07-07 13:20:28,816 INFO: Microblog startup [in /home/kodi/Workspace/parky/app/__init__.py:65]
2018-07-10 00:42:15,439 INFO: Microblog startup [in /home/kodi/Workspace/parky/app/__init__.py:65]
2018-07-10 00:42:34,929 INFO: Microblog startup [in /home/kodi/Workspace/parky/app/__init__.py:65]
2018-07-10 00:42:42,709 INFO: Microblog startup [in /home/kodi/Workspace/parky/app/__init__.py:65]
2018-07-10 00:43:23,158 INFO: Microblog startup [in /home/kodi/Workspace/parky/app/__init__.py:65]
2018-07-10 00:43:26,849 INFO: Microblog startup [in /home/kodi/Workspace/parky/app/__init__.py:65]
